<?xml version="1.0"?>
<robot xmlns:xacro="http://ros.org/wiki/xacro" name="prius">

  <!--- Surface properties must come first? -->
  <gazebo reference="front_left_wheel">
    <mu1>2.0</mu1>
    <mu2>2.0</mu2>
    <minDepth>0.005</minDepth>
    <kp>1e8</kp>
  </gazebo>
  <gazebo reference="front_right_wheel">
    <mu1>2.0</mu1>
    <mu2>2.0</mu2>
    <minDepth>0.005</minDepth>
    <kp>1e8</kp>
  </gazebo>
  <gazebo reference="rear_left_wheel">
    <mu1>2.0</mu1>
    <mu2>2.0</mu2>
    <minDepth>0.005</minDepth>
    <kp>1e8</kp>
  </gazebo>
  <gazebo reference="rear_right_wheel">
    <mu1>2.0</mu1>
    <mu2>2.0</mu2>
    <minDepth>0.005</minDepth>
    <kp>1e8</kp>
  </gazebo>

  <link name="base_link">
    <inertial>
      <mass value="1"/>
      <inertia ixx="0.001" ixy="0.0" ixz="0.0" iyy="0.001" iyz="0.0" izz="0.001"/>
    </inertial>
  </link>

  <joint name="base_link_connection" type="fixed">
    <parent link="base_link"/>
    <child link="chassis"/>
    <origin xyz="0 0 0" rpy="0 0 0"/>
    <axis xyz="1 0 0"/>
  </joint>

  <!-- <link name="chassis">
    <visual>
      <origin xyz="0.9 0.0 0.248" rpy="-1.5707 3.1415 0"/>
      <geometry>
        <mesh filename="package://ground_car/meshes/E02.obj" scale="0.001 0.001 0.001"/>
      </geometry>
    </visual> -->

  <link name="chassis">
    <visual>
      <origin xyz="0.9 0.0 0.248" rpy="-1.5707 3.1415 0"/>
        <geometry>
            <box size="2 0.9 0.496"/>
            <!-- <mesh filename="package://forklift_gazebo/meshes/fork_new_model.stl"/> -->
      </geometry>
    </visual>

    <collision name="chassis">
      <origin xyz="0.651 0.0 0.248" rpy="0 0 0"/>
        <geometry>
            <box size="2 0.9 0.496"/>
        </geometry>
    </collision>

    <inertial>
        <mass value="250.0"/>
        <origin xyz="0 0 0.0" rpy="0 0 0"/>
        <inertia ixx="2581.13354740" ixy="0.0" ixz="0.0" iyy="591.30846112" iyz="0.0" izz="2681.95008628"/>
    </inertial>
  </link>



  <link name="fl_axle">
    <inertial>
      <mass value="1"/>
      <origin xyz="0 0 0"/>
      <inertia ixx="0.004" ixy="0.0" ixz="0.0" iyy="0.004" iyz="0.0" izz="0.004"/>
    </inertial>
  </link>
  <link name="fr_axle">
    <inertial>
      <mass value="1"/>
      <origin xyz="0 0 0"/>
      <inertia ixx="0.004" ixy="0.0" ixz="0.0" iyy="0.004" iyz="0.0" izz="0.004"/>
    </inertial>
  </link>
  <link name="front_left_wheel">
    <inertial>
      <mass value="11"/>
      <origin xyz="0 0 0"/>
      <inertia ixx="0.58631238" ixy="0.0" ixz="0.0" iyy="0.33552910" iyz="0.0" izz="0.33552910"/>
    </inertial>
    <collision name="front_left_wheel_collision">
      <geometry>
        <sphere radius="0.2286"/>
      </geometry>
    </collision>
    <visual>
      <origin xyz="0 0 0" rpy="0 -1.5707 0"/>
      <geometry>
        <cylinder length="0.2032" radius="0.2286"/>
      </geometry>
        <transparency>0</transparency>
        <cast_shadows>1</cast_shadows>
    </visual>
  </link>
  <link name="front_right_wheel">
    <inertial>
      <mass value="11"/>
      <origin xyz="0 0 0"/>
      <inertia ixx="0.58631238" ixy="0.0" ixz="0.0" iyy="0.33552910" iyz="0.0" izz="0.33552910"/>
    </inertial>
    <collision name="front_right_wheel_collision">
      <geometry>
        <sphere radius="0.2286"/>
      </geometry>
    </collision>
    <visual>
      <origin xyz="0 0 0" rpy="0 -1.5707 0"/>
      <geometry>
        <cylinder length="0.2032" radius="0.2286"/>
      </geometry>
    </visual>
  </link>
  <link name="rear_left_wheel">
    <inertial>
      <mass value="11"/>
      <origin xyz="0 0 0"/>
      <inertia ixx="0.58631238" ixy="0.0" ixz="0.0" iyy="0.33552910" iyz="0.0" izz="0.33552910"/>
    </inertial>
    <collision name="rear_left_wheel_collision">
      <geometry>
        <sphere radius="0.2286"/>
      </geometry>
    </collision>
    <visual>
      <origin xyz="0 0 0" rpy="0 -1.5707 0"/>
      <geometry>
        <cylinder length="0.2032" radius="0.2286"/>
      </geometry>
    </visual>
  </link>
  <link name="rear_right_wheel">
    <inertial>
      <mass value="11"/>
      <origin xyz="0 0 0"/>
      <inertia ixx="0.58631238" ixy="0.0" ixz="0.0" iyy="0.33552910" iyz="0.0" izz="0.33552910"/>
    </inertial>
    <collision name="rear_right_wheel_collision">
      <geometry>
        <sphere radius="0.2286"/>
      </geometry>
    </collision>
    <visual>
      <origin xyz="0 0 0" rpy="0 -1.5707 0"/>
      <geometry>
        <cylinder length="0.2032" radius="0.2286"/>
      </geometry>
    </visual>
  </link>

  <joint name="front_left_steer_joint" type="continuous">
    <parent link="chassis"/>
    <child link="fl_axle"/>
    <origin xyz="0.889 0.605 0.1886" rpy="0 0 1.57"/>
    <axis xyz="0 0 1"/>
    <limit lower="-0.8727" upper="0.8727" effort="10000000" velocity="1000000"/>
  </joint>
  <joint name="front_right_steer_joint" type="continuous">
    <parent link="chassis"/>
    <child link="fr_axle"/>
    <origin xyz="0.889 -0.605 0.1886" rpy="0 0 1.57"/>
    <axis xyz="0 0 1"/>
    <limit lower="-0.8727" upper="0.8727" effort="10000000" velocity="1000000"/>
  </joint>
  <joint name="front_left_wheel_joint" type="continuous">
    <parent link="fl_axle"/>
    <child link="front_left_wheel"/>
    <origin xyz="0 0 0" rpy="0 0 0"/>
    <axis xyz="1 0 0"/>
  </joint>
  <joint name="front_right_wheel_joint" type="continuous">
    <parent link="fr_axle"/>
    <child link="front_right_wheel"/>
    <origin xyz="0 0 0" rpy="0 0 0"/>
    <axis xyz="1 0 0"/>
  </joint>
  <joint name="rear_left_wheel_joint" type="continuous">
    <parent link="chassis"/>
    <child link="rear_left_wheel"/>
    <origin xyz="-0.851 0.590 0.1886" rpy="0 0 1.57"/>
    <axis xyz="1 0 0"/>
  </joint>
  <joint name="rear_right_wheel_joint" type="continuous">
    <parent link="chassis"/>
    <child link="rear_right_wheel"/>
    <origin xyz="-0.851 -0.590 0.1886" rpy="0 0 1.57"/>
    <axis xyz="1 0 0"/>
  </joint>

  <!-- Sensor links and fixed joints -->
  <link name="center_laser_link">
    <inertial>
      <mass value="1"/>
      <inertia ixx="0.001" ixy="0.0" ixz="0.0" iyy="0.001" iyz="0.0" izz="0.001"/>
    </inertial>
  </link>
  <joint name="center_laser_joint" type="fixed">
    <parent link="chassis"/>
    <child link="center_laser_link"/>
    <origin xyz="1.3 0.0 0.0" rpy="0 0 0"/>
  </joint>


  <gazebo reference="base_link_connection">
    <disableFixedJointLumping>true</disableFixedJointLumping>
  </gazebo>
  

 
  <link name="front_camera_link">
    <inertial>
      <mass value="1"/>
      <inertia ixx="0.001" ixy="0.0" ixz="0.0" iyy="0.001" iyz="0.0" izz="0.001"/>
    </inertial>
  </link>
  <joint name="front_camera_joint" type="fixed">
    <parent link="chassis"/>
    <child link="front_camera_link"/>
    <origin xyz="0 0 1.1" rpy="0 0.17 0"/>
  </joint>


  <gazebo>
    <plugin name="pruis_hybrid_drive" filename="libPriusHybridPlugin.so">
      <chassis>chassis</chassis>
      <front_left_wheel>front_left_wheel_joint</front_left_wheel>
      <front_right_wheel>front_right_wheel_joint</front_right_wheel>
      <front_left_wheel_steering>front_left_steer_joint</front_left_wheel_steering>
      <front_right_wheel_steering>front_right_steer_joint</front_right_wheel_steering>
      <back_left_wheel>rear_left_wheel_joint</back_left_wheel>
      <back_right_wheel>rear_right_wheel_joint</back_right_wheel>
      <front_torque>0</front_torque>
      <back_torque>140</back_torque>
      <front_brake_torque>1031.28052716</front_brake_torque>
      <back_brake_torque>687.5203514400001</back_brake_torque>
      <max_speed>20</max_speed>
      <max_steer>0.44</max_steer>
      <flwheel_steering_p_gain>1e4</flwheel_steering_p_gain>
      <frwheel_steering_p_gain>1e4</frwheel_steering_p_gain>
      <flwheel_steering_i_gain>0</flwheel_steering_i_gain>
      <frwheel_steering_i_gain>0</frwheel_steering_i_gain>
      <flwheel_steering_d_gain>3e2</flwheel_steering_d_gain>
      <frwheel_steering_d_gain>3e2</frwheel_steering_d_gain>
      <flwheel_p_gain>0</flwheel_p_gain>
      <frwheel_p_gain>0</frwheel_p_gain>
      <flwheel_i_gain>0</flwheel_i_gain>
      <frwheel_i_gain>0</frwheel_i_gain>
      <flwheel_d_gain>0</flwheel_d_gain>
      <frwheel_d_gain>0</frwheel_d_gain>
      <blwheel_p_gain>300</blwheel_p_gain>
      <brwheel_p_gain>300</brwheel_p_gain>
      <blwheel_i_gain>0.001</blwheel_i_gain>
      <brwheel_i_gain>0.001</brwheel_i_gain>
      <blwheel_d_gain>0</blwheel_d_gain>
      <brwheel_d_gain>0</brwheel_d_gain>
    </plugin>
  </gazebo>

  <gazebo>
    <plugin name="joint_state_publisher" filename="libgazebo_ros_joint_state_publisher.so">
      <!-- <robotNamespace>/prius</robotNamespace> -->
      <jointName>rear_right_wheel_joint, rear_left_wheel_joint, front_right_wheel_joint, front_left_wheel_joint, front_right_steer_joint, front_left_steer_joint</jointName>
      <updateRate>100.0</updateRate>
      <alwaysOn>true</alwaysOn>
    </plugin>
  </gazebo>

  <gazebo>
    <plugin name="p3d" filename="libgazebo_ros_p3d.so">
      <!-- <robotNamespace>/prius</robotNamespace> -->
      <bodyName>chassis</bodyName>
      <topicName>base_pose_ground_truth</topicName>
      <frameName>map</frameName>
      <updateRate>100.0</updateRate>
    </plugin>
  </gazebo>


 <gazebo reference="center_laser_link">
    <sensor name='center_laser_sensor' type='ray'>
      <ray>
         <scan>
	        <pose>0 0 0 0 0 0</pose>
            <vertical>
              <samples>32</samples>
              <resolution>1</resolution>
              <min_angle>-0.5352</min_angle>
              <max_angle>0.1862</max_angle>
            </vertical>
            <horizontal>
              <samples>500</samples>
              <resolution>1</resolution>
              <min_angle>-3.1415</min_angle>
              <max_angle>3.1415</max_angle>
            </horizontal>
          </scan>
          <range>
            <min>0.9</min>
            <max>131</max>
            <resolution>0.001</resolution>
          </range>
          <noise>
            <type>gaussian</type>
            <mean>0.0</mean>
            <stddev>0</stddev>
          </noise>
      </ray>
      <plugin name="gazebo_ros_laser_controller" filename="libgazebo_ros_velodyne_laser.so">
          <topicName>/velodyne_points</topicName>
          <frameName>center_laser_link</frameName>
          <min_range>0.9</min_range>
          <max_range>130</max_range>
          <gaussianNoise>0</gaussianNoise>
        </plugin>
      <always_on>1</always_on>
      <update_rate>10</update_rate>
      <visualize>0</visualize>
    </sensor>
   </gazebo>

  <gazebo reference="front_camera_link">
    <sensor type="camera" name="front_camera_sensor">
      <update_rate>30.0</update_rate>
      <camera name="front_camera">
        <horizontal_fov>1.3962634</horizontal_fov>
        <image>
          <width>800</width>
          <height>800</height>
          <format>R8G8B8</format>
        </image>
        <clip>
          <near>0.02</near>
          <far>300</far>
        </clip>
        <noise>
          <type>gaussian</type>
          <mean>0.0</mean>
          <stddev>0.007</stddev>
        </noise>
      </camera>
      <plugin name="front_camera_controller" filename="libgazebo_ros_camera.so">
        <alwaysOn>false</alwaysOn>
        <updateRate>0.0</updateRate>
        <cameraName>/E02/front_camera</cameraName>
        <imageTopicName>image_raw</imageTopicName>
        <cameraInfoTopicName>/E02/front_camera_info</cameraInfoTopicName>
        <frameName>camera_link</frameName>
        <hackBaseline>0.07</hackBaseline>
        <distortionK1>0.0</distortionK1>
        <distortionK2>0.0</distortionK2>
        <distortionK3>0.0</distortionK3>
        <distortionT1>0.0</distortionT1>
        <distortionT2>0.0</distortionT2>
      </plugin>
    </sensor>
  </gazebo>

</robot>
